---
title: C6322
ms.date: 11/04/2016
ms.topic: reference
f1_keywords:
- C6322
helpviewer_keywords:
- C6322
ms.assetid: fb23d2b1-b2a0-465c-8bf5-ec039c6c7757
ms.openlocfilehash: 47e65bfa5b350f298bf26e739a35b0f8ff4c517c
ms.sourcegitcommit: 7bea0420d0e476287641edeb33a9d5689a98cb98
ms.translationtype: MT
ms.contentlocale: es-ES
ms.lasthandoff: 02/17/2020
ms.locfileid: "79467956"
---
# <a name="c6322"></a>C6322

> ADVERTENCIA C6322: bloque de _except vacío

Este mensaje indica que no hay ningún código en el bloque _except. Como resultado, es posible que las excepciones no estén controladas.

## <a name="example"></a>Ejemplo

El código siguiente genera esta advertencia:

```cpp
#include <stdio.h>
#include <excpt.h>
#include <windows.h>

void fd(char *pch)
{
   __try
   {
     // exception rasied if pch is null
     *pch= 0 ;
   }
   __except(GetExceptionCode() == EXCEPTION_ACCESS_VIOLATION)
   {
   }
}
```

Para corregir esta advertencia, utilice el código siguiente:

```cpp
#include <stdio.h>
#include <excpt.h>
#include <windows.h>

void f(char *pch)
{
   __try
   {
     // exception rasied if pch is null
    *pch= 0 ;
   }
   __except(GetExceptionCode() == EXCEPTION_ACCESS_VIOLATION ?
               EXCEPTION_EXECUTE_HANDLER : EXCEPTION_CONTINUE_SEARCH)
   {
     // code to handle exception
     puts("Exception Occurred");
   }
}
```

## <a name="see-also"></a>Consulte también

[try-except (Instrucción)](/cpp/cpp/try-except-statement)
